Workbook

Sheet Dashboard
A1: REDIP — Deal Dashboard
A3: Scenario: | B3: ='Model Engine'!B4 | C3: Hurdle Rate: | D3: =Inputs!B49 | E3: Period End Dates → | F3: =TEXT('Model Engine'!$B$30,"mmm-yy")&" … "&TEXT('Model Engine'!$U$30,"mmm-yy")
A5: Unlevered IRR | B5: ='Returns & Sensitivity'!B4 | C5: Levered IRR | D5: ='Returns & Sensitivity'!B5 | E5: Equity Invested | F5: ='Returns & Sensitivity'!B8 | G5: MOIC (Levered) | H5: ='Returns & Sensitivity'!B11
A7: Project Profit | B7: ='Returns & Sensitivity'!B13 | C7: Profit Margin | D7: ='Returns & Sensitivity'!B14 | E7: Unlevered NPV | F7: ='Returns & Sensitivity'!B6 | G7: Levered NPV | H7: ='Returns & Sensitivity'!B7
A9: Total Project Cost | B9: ='Model Engine'!B24 | C9: Max Loan (LTC) | D9: ='Model Engine'!B25 | E9: Gross Revenue | F9: =SUM('Model Engine'!$B$49:$U$49)+SUM('Model Engine'!$B$47:$U$47)*-1+SUM('Model Engine'!$B$48:$U$48)*-1 | G9: Saleable Area | H9: ='Model Engine'!B12
A62: CHART DATA (linked from Engine — do not edit)
A63: Period End | B63: ='Model Engine'!B30 | C63: ='Model Engine'!C30 | D63: ='Model Engine'!D30 | E63: ='Model Engine'!E30 | F63: ='Model Engine'!F30 | G63: ='Model Engine'!G30 | H63: ='Model Engine'!H30 | I63: ='Model Engine'!I30 | ... U63: ='Model Engine'!U30
A64: Unlev CF | B64: ='Model Engine'!B51 | C64: ='Model Engine'!C51 | D64: ='Model Engine'!D51 | E64: ='Model Engine'!E51 | F64: ='Model Engine'!F51 | G64: ='Model Engine'!G51 | H64: ='Model Engine'!H51 | I64: ='Model Engine'!I51 | ... U64: ='Model Engine'!U51
A65: Equity CF | B65: ='Model Engine'!B60 | C65: ='Model Engine'!C60 | D65: ='Model Engine'!D60 | E65: ='Model Engine'!E60 | F65: ='Model Engine'!F60 | G65: ='Model Engine'!G60 | H65: ='Model Engine'!H60 | I65: ='Model Engine'!I60 | ... U65: ='Model Engine'!U60
A66: Cum Equity CF | B66: ='Model Engine'!B61 | C66: ='Model Engine'!C61 | D66: ='Model Engine'!D61 | E66: ='Model Engine'!E61 | F66: ='Model Engine'!F61 | G66: ='Model Engine'!G61 | H66: ='Model Engine'!H61 | I66: ='Model Engine'!I61 | ... U66: ='Model Engine'!U61
A68: Total Outflow | B68: =SUM('Model Engine'!$B$42:$U$42)
A69: Net Revenue | B69: =SUM('Model Engine'!$B$49:$U$49)
A71: Equity | B71: ='Returns & Sensitivity'!B9
A72: Debt | B72: =SUM('Model Engine'!$B$53:$U$53)
A74: Land | B74: ='Model Engine'!B18
A75: Dev Cost | B75: ='Model Engine'!B23
A76: Interest | B76: =SUM('Model Engine'!$B$56:$U$56)

Sheet Inputs
A1: REDIP — Real Estate Development Model | INPUTS (all blue cells are hardcoded)
A3: 1. SCENARIO SELECTOR
A4: Active Scenario (1=Base, 2=Upside, 3=Downside) | B4: 1 | C4: # | D4: Engine picks scenario row via INDEX on this index.
A6: Scenario | B6: Price Factor | C6: Cost Factor | D6: Exit Factor
A7: Base | B7: 1 | C7: 1 | D7: 1
A8: Upside | B8: 1.1 | C8: 0.96 | D8: 1.05
A9: Downside | B9: 0.9 | C9: 1.07 | D9: 0.92
A11: 2. LAND
A12: Site Area | B12: 5 | C12: acres | D12: Raw land parcel area
A13: Land Price | B13: 150 | C13: ₹ Cr | D13: All-in land consideration
A14: Stamp Duty + Registration | B14: 0.065 | C14: % | D14: Karnataka typical 5-6.6%
A15: Land Acquisition Month | B15: 0 | C15: month | D15: 0 = project start
A17: 3. DEVELOPMENT COSTS
A18: FSI / FAR | B18: 2.5 | C18: x | D18: Built-up / Site
A19: Saleable Efficiency | B19: 0.82 | C19: % | D19: Saleable / Built-up
A20: Hard Construction Cost | B20: 3500 | C20: ₹/sqft | D20: On built-up area
A21: Soft Cost % of Hard | B21: 0.15 | C21: % | D21: Design, PMC, marketing setup
A22: Approvals & Fees | B22: 8 | C22: ₹ Cr | D22: RERA, BBMP, BWSSB, BESCOM etc.
A23: Contingency % of Hard+Soft | B23: 0.05 | C23: % | D23: Reserve
A24: Construction Start Month | B24: 3 | C24: month | D24: Offset from project start
A25: Construction Duration | B25: 24 | C25: months | D25: Linear spend assumed
A27: 4. REVENUE
A28: Sale Price | B28: 12000 | C28: ₹/sqft | D28: Market price on saleable
A29: Price Escalation p.a. | B29: 0.04 | C29: % | D29: Compounded per year
A30: Sales Start Month | B30: 9 | C30: month | D30: Usually after soft-launch
A31: Sales Duration | B31: 30 | C31: months | D31: Linear absorption window
A32: Sales Commission | B32: 0.02 | C32: % | D32: Broker + internal
A33: GST & Other Sale Costs | B33: 0.05 | C33: % | D33: Net to developer reduction
A35: 5. DEBT
A36: Loan to Cost (LTC) | B36: 0.55 | C36: % | D36: Applied to dev cost only
A37: Interest Rate p.a. | B37: 0.11 | C37: % | D37: Annual, compounded quarterly
A38: Drawdown Start Month | B38: 3 | C38: month | D38: Usually = construction start
A39: Drawdown End Month | B39: 27 | C39: month | D39: Usually = construction end
A41: 6. TIMELINE & PERIODICITY
A42: Model Start Date | B42: 46113 | C42: date | D42: Dates used for XIRR/XNPV
A43: Period Length | B43: 3 | C43: months | D43: Quarterly grid
A44: Number of Periods | B44: 20 | C44: # | D44: 5 years quarterly
A46: 7. EXIT / RESIDUAL
A47: Bulk Exit % of Saleable | B47: 0.15 | C47: % | D47: Sold at end of sales window
A48: Exit Price Factor | B48: 0.95 | C48: % | D48: Discount/premium on market
...

Sheet Model Engine
A1: REDIP — Model Engine | all formulas, no hardcoding
A3: SCENARIO LOOKUP (driven by Inputs!B4)
A4: Active Scenario | B4: =CHOOSE(Inputs!$B$4,"Base","Upside","Downside")
A5: Price Multiplier | B5: =INDEX(Inputs!$B$7:$B$9,Inputs!$B$4)
A6: Cost Multiplier | B6: =INDEX(Inputs!$C$7:$C$9,Inputs!$B$4)
A7: Exit Multiplier | B7: =INDEX(Inputs!$D$7:$D$9,Inputs!$B$4)
A9: DERIVED CONSTANTS
A10: Site Area | B10: =Inputs!B12*43560
A11: Built-up Area | B11: =B10*Inputs!B18
A12: Saleable Area | B12: =B11*Inputs!B19
A13: Effective Sale Price | B13: =Inputs!B28*$B$5
A14: Effective Hard Cost | B14: =Inputs!B20*$B$6
A15: Quarterly Interest Rate | B15: =(1+Inputs!B37)^(Inputs!B43/12)-1
A17: PROJECT TOTALS (₹ Cr)
A18: Land Cost (incl. Stamp Duty) | B18: =Inputs!B13*(1+Inputs!B14)
A19: Hard Construction | B19: =B11*$B$14/10000000
A20: Soft Costs | B20: =B19*Inputs!B21
A21: Approvals & Fees | B21: =Inputs!B22
A22: Contingency | B22: =(B19+B20)*Inputs!B23
A23: Total Development Cost | B23: =SUM(B19:B22)
A24: Total Project Cost | B24: =B18+B23
A25: Max Loan (LTC × Dev) | B25: =B23*Inputs!B36
A26: QUARTERLY CASH FLOW GRID
A27: Period # | B27: 1 | C27: 2 | D27: 3 | E27: 4 | F27: 5 | G27: 6 | H27: 7 | I27: 8 | J27: 9 | K27: 10 | L27: 11 | M27: 12 | N27: 13 | O27: 14 | P27: 15 | Q27: 16 | R27: 17 | S27: 18 | T27: 19 | U27: 20
A28: Month Start | B28: =(1-1)*Inputs!$B$43 | C28: =(2-1)*Inputs!$B$43 | D28: =(3-1)*Inputs!$B$43 | E28: =(4-1)*Inputs!$B$43 | F28: =(5-1)*Inputs!$B$43 | G28: =(6-1)*Inputs!$B$43 | H28: =(7-1)*Inputs!$B$43 | I28: =(8-1)*Inputs!$B$43 | J28: =(9-1)*Inputs!$B$43 | K28: =(10-1)*Inputs!$B$43 | L28: =(11-1)*Inputs!$B$43 | M28: =(12-1)*Inputs!$B$43 | N28: =(13-1)*Inputs!$B$43 | O28: =(14-1)*Inputs!$B$43 | P28: =(15-1)*Inputs!$B$43 | Q28: =(16-1)*Inputs!$B$43 | R28: =(17-1)*Inputs!$B$43 | S28: =(18-1)*Inputs!$B$43 | T28: =(19-1)*Inputs!$B$43 | U28: =(20-1)*Inputs!$B$43
A29: Month End | B29: =1*Inputs!$B$43 | C29: =2*Inputs!$B$43 | D29: =3*Inputs!$B$43 | E29: =4*Inputs!$B$43 | F29: =5*Inputs!$B$43 | G29: =6*Inputs!$B$43 | H29: =7*Inputs!$B$43 | I29: =8*Inputs!$B$43 | J29: =9*Inputs!$B$43 | K29: =10*Inputs!$B$43 | L29: =11*Inputs!$B$43 | M29: =12*Inputs!$B$43 | N29: =13*Inputs!$B$43 | O29: =14*Inputs!$B$43 | P29: =15*Inputs!$B$43 | Q29: =16*Inputs!$B$43 | R29: =17*Inputs!$B$43 | S29: =18*Inputs!$B$43 | T29: =19*Inputs!$B$43 | U29: =20*Inputs!$B$43
A30: Period End Date | B30: =EDATE(Inputs!$B$42,B$29) | C30: =EDATE(Inputs!$B$42,C$29) | D30: =EDATE(Inputs!$B$42,D$29) | E30: =EDATE(Inputs!$B$42,E$29) | F30: =EDATE(Inputs!$B$42,F$29) | G30: =EDATE(Inputs!$B$42,G$29) | H30: =EDATE(Inputs!$B$42,H$29) | I30: =EDATE(Inputs!$B$42,I$29) | ... U30: =EDATE(Inputs!$B$42,U$29)
A31: Construction Phasing % | B31: =MAX(0,MIN(Inputs!$B$24+Inputs!$B$25,B$29)-MAX(Inputs!$B$24,B$28))/Inputs!$B$25 | C31: =MAX(0,MIN(Inputs!$B$24+Inputs!$B$25,C$29)-MAX(Inputs!$B$24,C$28))/Inputs!$B$25 | D31: =MAX(0,MIN(Inputs!$B$24+Inputs!$B$25,D$29)-MAX(Inputs!$B$24,D$28))/Inputs!$B$25 | E31: =MAX(0,MIN(Inputs!$B$24+Inputs!$B$25,E$29)-MAX(Inputs!$B$24,E$28))/Inputs!$B$25 | F31: =MAX(0,MIN(Inputs!$B$24+Inputs!$B$25,F$29)-MAX(Inputs!$B$24,F$28))/Inputs!$B$25 | G31: =MAX(0,MIN(Inputs!$B$24+Inputs!$B$25,G$29)-MAX(Inputs!$B$24,G$28))/Inputs!$B$25 | H31: =MAX(0,MIN(Inputs!$B$24+Inputs!$B$25,H$29)-MAX(Inputs!$B$24,H$28))/Inputs!$B$25 | I31: =MAX(0,MIN(Inputs!$B$24+Inputs!$B$25,I$29)-MAX(Inputs!$B$24,I$28))/Inputs!$B$25 | ... U31: =MAX(0,MIN(Inputs!$B$24+Inputs!$B$25,U$29)-MAX(Inputs!$B$24,U$28))/Inputs!$B$25
A32: Absorption Phasing % | B32: =MAX(0,MIN(Inputs!$B$30+Inputs!$B$31,B$29)-MAX(Inputs!$B$30,B$28))/Inputs!$B$31*(1-Inputs!$B$47) | C32: =MAX(0,MIN(Inputs!$B$30+Inputs!$B$31,C$29)-MAX(Inputs!$B$30,C$28))/Inputs!$B$31*(1-Inputs!$B$47) | D32: =MAX(0,MIN(Inputs!$B$30+Inputs!$B$31,D$29)-MAX(Inputs!$B$30,D$28))/Inputs!$B$31*(1-Inputs!$B$47) | E32: =MAX(0,MIN(Inputs!$B$30+Inputs!$B$31,E$29)-MAX(Inputs!$B$30,E$28))/Inputs!$B$31*(1-Inputs!$B$47) | F32: =MAX(0,MIN(Inputs!$B$30+Inputs!$B$31,F$29)-MAX(Inputs!$B$30,F$28))/Inputs!$B$31*(1-Inputs!$B$47) | G32: =MAX(0,MIN(Inputs!$B$30+Inputs!$B$31,G$29)-MAX(Inputs!$B$30,G$28))/Inputs!$B$31*(1-Inputs!$B$47) | H32: =MAX(0,MIN(Inputs!$B$30+Inputs!$B$31,H$29)-MAX(Inputs!$B$30,H$28))/Inputs!$B$31*(1-Inputs!$B$47) | I32: =MAX(0,MIN(Inputs!$B$30+Inputs!$B$31,I$29)-MAX(Inputs!$B$30,I$28))/Inputs!$B$31*(1-Inputs!$B$47) | ... U32: =MAX(0,MIN(Inputs!$B$30+Inputs!$B$31,U$29)-MAX(Inputs!$B$30,U$28))/Inputs!$B$31*(1-Inputs!$B$47)
A33: Bulk Exit Indicator | B33: =IF(AND(Inputs!$B$30+Inputs!$B$31>B$28,Inputs!$B$30+Inputs!$B$31<=B$29),1,0) | C33: =IF(AND(Inputs!$B$30+Inputs!$B$31>C$28,Inputs!$B$30+Inputs!$B$31<=C$29),1,0) | D33: =IF(AND(Inputs!$B$30+Inputs!$B$31>D$28,Inputs!$B$30+Inputs!$B$31<=D$29),1,0) | E33: =IF(AND(Inputs!$B$30+Inputs!$B$31>E$28,Inputs!$B$30+Inputs!$B$31<=E$29),1,0) | F33: =IF(AND(Inputs!$B$30+Inputs!$B$31>F$28,Inputs!$B$30+Inputs!$B$31<=F$29),1,0) | G33: =IF(AND(Inputs!$B$30+Inputs!$B$31>G$28,Inputs!$B$30+Inputs!$B$31<=G$29),1,0) | H33: =IF(AND(Inputs!$B$30+Inputs!$B$31>H$28,Inputs!$B$30+Inputs!$B$31<=H$29),1,0) | I33: =IF(AND(Inputs!$B$30+Inputs!$B$31>I$28,Inputs!$B$30+Inputs!$B$31<=I$29),1,0) | ... U33: =IF(AND(Inputs!$B$30+Inputs!$B$31>U$28,Inputs!$B$30+Inputs!$B$31<=U$29),1,0)
A34: Mid-period Month | B34: =(B$28+B$29)/2 | C34: =(C$28+C$29)/2 | D34: =(D$28+D$29)/2 | E34: =(E$28+E$29)/2 | F34: =(F$28+F$29)/2 | G34: =(G$28+G$29)/2 | H34: =(H$28+H$29)/2 | I34: =(I$28+I$29)/2 | ... U34: =(U$28+U$29)/2
A36: Land Outflow | B36: =IF(AND(Inputs!$B$15>=B$28,Inputs!$B$15<B$29),$B$18,0) | C36: =IF(AND(Inputs!$B$15>=C$28,Inputs!$B$15<C$29),$B$18,0) | D36: =IF(AND(Inputs!$B$15>=D$28,Inputs!$B$15<D$29),$B$18,0) | E36: =IF(AND(Inputs!$B$15>=E$28,Inputs!$B$15<E$29),$B$18,0) | F36: =IF(AND(Inputs!$B$15>=F$28,Inputs!$B$15<F$29),$B$18,0) | G36: =IF(AND(Inputs!$B$15>=G$28,Inputs!$B$15<G$29),$B$18,0) | H36: =IF(AND(Inputs!$B$15>=H$28,Inputs!$B$15<H$29),$B$18,0) | I36: =IF(AND(Inputs!$B$15>=I$28,Inputs!$B$15<I$29),$B$18,0) | ... U36: =IF(AND(Inputs!$B$15>=U$28,Inputs!$B$15<U$29),$B$18,0)
A37: Hard Construction | B37: =$B$19*B$31 | C37: =$B$19*C$31 | D37: =$B$19*D$31 | E37: =$B$19*E$31 | F37: =$B$19*F$31 | G37: =$B$19*G$31 | H37: =$B$19*H$31 | I37: =$B$19*I$31 | ... U37: =$B$19*U$31
A38: Soft Costs | B38: =$B$20*B$31 | C38: =$B$20*C$31 | D38: =$B$20*D$31 | E38: =$B$20*E$31 | F38: =$B$20*F$31 | G38: =$B$20*G$31 | H38: =$B$20*H$31 | I38: =$B$20*I$31 | ... U38: =$B$20*U$31
A39: Approvals & Fees | B39: =$B$21*B$31 | C39: =$B$21*C$31 | D39: =$B$21*D$31 | E39: =$B$21*E$31 | F39: =$B$21*F$31 | G39: =$B$21*G$31 | H39: =$B$21*H$31 | I39: =$B$21*I$31 | ... U39: =$B$21*U$31
A40: Contingency | B40: =$B$22*B$31 | C40: =$B$22*C$31 | D40: =$B$22*D$31 | E40: =$B$22*E$31 | F40: =$B$22*F$31 | G40: =$B$22*G$31 | H40: =$B$22*H$31 | I40: =$B$22*I$31 | ... U40: =$B$22*U$31
A41: Total Dev Outflow | B41: =SUM(B37:B40) | C41: =SUM(C37:C40) | D41: =SUM(D37:D40) | E41: =SUM(E37:E40) | F41: =SUM(F37:F40) | G41: =SUM(G37:G40) | H41: =SUM(H37:H40) | I41: =SUM(I37:I40) | ... U41: =SUM(U37:U40)
A42: TOTAL OUTFLOW | B42: =B36+B41 | C42: =C36+C41 | D42: =D36+D41 | E42: =E36+E41 | F42: =F36+F41 | G42: =G36+G41 | H42: =H36+H41 | I42: =I36+I41 | ... U42: =U36+U41
A44: Absorption Gross Revenue | B44: =$B$12*$B$13*B$32*(1+Inputs!$B$29)^(B$34/12)/10000000 | C44: =$B$12*$B$13*C$32*(1+Inputs!$B$29)^(C$34/12)/10000000 | D44: =$B$12*$B$13*D$32*(1+Inputs!$B$29)^(D$34/12)/10000000 | E44: =$B$12*$B$13*E$32*(1+Inputs!$B$29)^(E$34/12)/10000000 | F44: =$B$12*$B$13*F$32*(1+Inputs!$B$29)^(F$34/12)/10000000 | G44: =$B$12*$B$13*G$32*(1+Inputs!$B$29)^(G$34/12)/10000000 | H44: =$B$12*$B$13*H$32*(1+Inputs!$B$29)^(H$34/12)/10000000 | I44: =$B$12*$B$13*I$32*(1+Inputs!$B$29)^(I$34/12)/10000000 | ... U44: =$B$12*$B$13*U$32*(1+Inputs!$B$29)^(U$34/12)/10000000
A45: Exit Gross Revenue | B45: =$B$12*Inputs!$B$47*$B$13*Inputs!$B$48*$B$7*(1+Inputs!$B$29)^(B$34/12)*B$33/10000000 | C45: =$B$12*Inputs!$B$47*$B$13*Inputs!$B$48*$B$7*(1+Inputs!$B$29)^(C$34/12)*C$33/10000000 | D45: =$B$12*Inputs!$B$47*$B$13*Inputs!$B$48*$B$7*(1+Inputs!$B$29)^(D$34/12)*D$33/10000000 | E45: =$B$12*Inputs!$B$47*$B$13*Inputs!$B$48*$B$7*(1+Inputs!$B$29)^(E$34/12)*E$33/10000000 | F45: =$B$12*Inputs!$B$47*$B$13*Inputs!$B$48*$B$7*(1+Inputs!$B$29)^(F$34/12)*F$33/10000000 | G45: =$B$12*Inputs!$B$47*$B$13*Inputs!$B$48*$B$7*(1+Inputs!$B$29)^(G$34/12)*G$33/10000000 | H45: =$B$12*Inputs!$B$47*$B$13*Inputs!$B$48*$B$7*(1+Inputs!$B$29)^(H$34/12)*H$33/10000000 | I45: =$B$12*Inputs!$B$47*$B$13*Inputs!$B$48*$B$7*(1+Inputs!$B$29)^(I$34/12)*I$33/10000000 | ... U45: =$B$12*Inputs!$B$47*$B$13*Inputs!$B$48*$B$7*(1+Inputs!$B$29)^(U$34/12)*U$33/10000000
...

Sheet Returns & Sensitivity
A1: REDIP — Returns & Sensitivity
A3: PROJECT RETURNS
A4: Unlevered IRR (XIRR) | B4: =IFERROR(XIRR('Model Engine'!$B$51:$U$51,'Model Engine'!$B$30:$U$30),"n/a")
A5: Levered IRR (XIRR) | B5: =IFERROR(XIRR('Model Engine'!$B$60:$U$60,'Model Engine'!$B$30:$U$30),"n/a")
A6: Unlevered NPV (XNPV @ Hurdle) | B6: =XNPV(Inputs!$B$49,'Model Engine'!$B$51:$U$51,'Model Engine'!$B$30:$U$30)
A7: Levered NPV (XNPV @ Hurdle) | B7: =XNPV(Inputs!$B$49,'Model Engine'!$B$60:$U$60,'Model Engine'!$B$30:$U$30)
A8: Equity Invested (Peak) | B8: =ABS(MIN('Model Engine'!$B$61:$U$61))
A9: Total Equity Outflow | B9: =SUMIF('Model Engine'!$B$60:$U$60,"<0",'Model Engine'!$B$60:$U$60)*-1
A10: Total Equity Inflow | B10: =SUMIF('Model Engine'!$B$60:$U$60,">0",'Model Engine'!$B$60:$U$60)
A11: MOIC (Levered) | B11: =IFERROR(B10/B9,"n/a")
A12: Equity Multiple (Net of Return of Capital) | B12: =IFERROR((B10-B9)/B9,"n/a")
A13: Project Profit | B13: =SUM('Model Engine'!$B$49:$U$49)-SUM('Model Engine'!$B$42:$U$42)
A14: Profit Margin (on Revenue) | B14: =IFERROR(B13/SUM('Model Engine'!$B$49:$U$49),"n/a")
A16: SENSITIVITY — PRICE SHIFT vs UNLEVERED IRR
A17: Price Shift | B17: Unlev IRR | C17: MOIC (Unlev) | E17: Helper CF strip → | F17: P1 | G17: P2 | H17: P3 | I17: P4 | J17: P5 | K17: P6 | L17: P7 | M17: P8 | N17: P9 | O17: P10 | P17: P11 | Q17: P12 | R17: P13 | S17: P14 | T17: P15 | U17: P16 | V17: P17 | W17: P18 | X17: P19 | Y17: P20
B18: =IFERROR(XIRR($F18:$Y18,'Model Engine'!$B$30:$U$30),"n/a") | C18: =IFERROR(SUMIF($F18:$Y18,">0")/(-SUMIF($F18:$Y18,"<0")),"n/a") | F18: ='Model Engine'!B49*(1+$A18)-'Model Engine'!B42 | G18: ='Model Engine'!C49*(1+$A18)-'Model Engine'!C42 | H18: ='Model Engine'!D49*(1+$A18)-'Model Engine'!D42 | I18: ='Model Engine'!E49*(1+$A18)-'Model Engine'!E42 | J18: ='Model Engine'!F49*(1+$A18)-'Model Engine'!F42 | K18: ='Model Engine'!G49*(1+$A18)-'Model Engine'!G42 | L18: ='Model Engine'!H49*(1+$A18)-'Model Engine'!H42 | M18: ='Model Engine'!I49*(1+$A18)-'Model Engine'!I42 | ... Y18: ='Model Engine'!U49*(1+$A18)-'Model Engine'!U42
B19: =IFERROR(XIRR($F19:$Y19,'Model Engine'!$B$30:$U$30),"n/a") | C19: =IFERROR(SUMIF($F19:$Y19,">0")/(-SUMIF($F19:$Y19,"<0")),"n/a") | F19: ='Model Engine'!B49*(1+$A19)-'Model Engine'!B42 | G19: ='Model Engine'!C49*(1+$A19)-'Model Engine'!C42 | H19: ='Model Engine'!D49*(1+$A19)-'Model Engine'!D42 | I19: ='Model Engine'!E49*(1+$A19)-'Model Engine'!E42 | J19: ='Model Engine'!F49*(1+$A19)-'Model Engine'!F42 | K19: ='Model Engine'!G49*(1+$A19)-'Model Engine'!G42 | L19: ='Model Engine'!H49*(1+$A19)-'Model Engine'!H42 | M19: ='Model Engine'!I49*(1+$A19)-'Model Engine'!I42 | ... Y19: ='Model Engine'!U49*(1+$A19)-'Model Engine'!U42
B20: =IFERROR(XIRR($F20:$Y20,'Model Engine'!$B$30:$U$30),"n/a") | C20: =IFERROR(SUMIF($F20:$Y20,">0")/(-SUMIF($F20:$Y20,"<0")),"n/a") | F20: ='Model Engine'!B49*(1+$A20)-'Model Engine'!B42 | G20: ='Model Engine'!C49*(1+$A20)-'Model Engine'!C42 | H20: ='Model Engine'!D49*(1+$A20)-'Model Engine'!D42 | I20: ='Model Engine'!E49*(1+$A20)-'Model Engine'!E42 | J20: ='Model Engine'!F49*(1+$A20)-'Model Engine'!F42 | K20: ='Model Engine'!G49*(1+$A20)-'Model Engine'!G42 | L20: ='Model Engine'!H49*(1+$A20)-'Model Engine'!H42 | M20: ='Model Engine'!I49*(1+$A20)-'Model Engine'!I42 | ... Y20: ='Model Engine'!U49*(1+$A20)-'Model Engine'!U42
B21: =IFERROR(XIRR($F21:$Y21,'Model Engine'!$B$30:$U$30),"n/a") | C21: =IFERROR(SUMIF($F21:$Y21,">0")/(-SUMIF($F21:$Y21,"<0")),"n/a") | F21: ='Model Engine'!B49*(1+$A21)-'Model Engine'!B42 | G21: ='Model Engine'!C49*(1+$A21)-'Model Engine'!C42 | H21: ='Model Engine'!D49*(1+$A21)-'Model Engine'!D42 | I21: ='Model Engine'!E49*(1+$A21)-'Model Engine'!E42 | J21: ='Model Engine'!F49*(1+$A21)-'Model Engine'!F42 | K21: ='Model Engine'!G49*(1+$A21)-'Model Engine'!G42 | L21: ='Model Engine'!H49*(1+$A21)-'Model Engine'!H42 | M21: ='Model Engine'!I49*(1+$A21)-'Model Engine'!I42 | ... Y21: ='Model Engine'!U49*(1+$A21)-'Model Engine'!U42
B22: =IFERROR(XIRR($F22:$Y22,'Model Engine'!$B$30:$U$30),"n/a") | C22: =IFERROR(SUMIF($F22:$Y22,">0")/(-SUMIF($F22:$Y22,"<0")),"n/a") | F22: ='Model Engine'!B49*(1+$A22)-'Model Engine'!B42 | G22: ='Model Engine'!C49*(1+$A22)-'Model Engine'!C42 | H22: ='Model Engine'!D49*(1+$A22)-'Model Engine'!D42 | I22: ='Model Engine'!E49*(1+$A22)-'Model Engine'!E42 | J22: ='Model Engine'!F49*(1+$A22)-'Model Engine'!F42 | K22: ='Model Engine'!G49*(1+$A22)-'Model Engine'!G42 | L22: ='Model Engine'!H49*(1+$A22)-'Model Engine'!H42 | M22: ='Model Engine'!I49*(1+$A22)-'Model Engine'!I42 | ... Y22: ='Model Engine'!U49*(1+$A22)-'Model Engine'!U42
B23: =IFERROR(XIRR($F23:$Y23,'Model Engine'!$B$30:$U$30),"n/a") | C23: =IFERROR(SUMIF($F23:$Y23,">0")/(-SUMIF($F23:$Y23,"<0")),"n/a") | F23: ='Model Engine'!B49*(1+$A23)-'Model Engine'!B42 | G23: ='Model Engine'!C49*(1+$A23)-'Model Engine'!C42 | H23: ='Model Engine'!D49*(1+$A23)-'Model Engine'!D42 | I23: ='Model Engine'!E49*(1+$A23)-'Model Engine'!E42 | J23: ='Model Engine'!F49*(1+$A23)-'Model Engine'!F42 | K23: ='Model Engine'!G49*(1+$A23)-'Model Engine'!G42 | L23: ='Model Engine'!H49*(1+$A23)-'Model Engine'!H42 | M23: ='Model Engine'!I49*(1+$A23)-'Model Engine'!I42 | ... Y23: ='Model Engine'!U49*(1+$A23)-'Model Engine'!U42
B24: =IFERROR(XIRR($F24:$Y24,'Model Engine'!$B$30:$U$30),"n/a") | C24: =IFERROR(SUMIF($F24:$Y24,">0")/(-SUMIF($F24:$Y24,"<0")),"n/a") | F24: ='Model Engine'!B49*(1+$A24)-'Model Engine'!B42 | G24: ='Model Engine'!C49*(1+$A24)-'Model Engine'!C42 | H24: ='Model Engine'!D49*(1+$A24)-'Model Engine'!D42 | I24: ='Model Engine'!E49*(1+$A24)-'Model Engine'!E42 | J24: ='Model Engine'!F49*(1+$A24)-'Model Engine'!F42 | K24: ='Model Engine'!G49*(1+$A24)-'Model Engine'!G42 | L24: ='Model Engine'!H49*(1+$A24)-'Model Engine'!H42 | M24: ='Model Engine'!I49*(1+$A24)-'Model Engine'!I42 | ... Y24: ='Model Engine'!U49*(1+$A24)-'Model Engine'!U42
B25: =IFERROR(XIRR($F25:$Y25,'Model Engine'!$B$30:$U$30),"n/a") | C25: =IFERROR(SUMIF($F25:$Y25,">0")/(-SUMIF($F25:$Y25,"<0")),"n/a") | F25: ='Model Engine'!B49*(1+$A25)-'Model Engine'!B42 | G25: ='Model Engine'!C49*(1+$A25)-'Model Engine'!C42 | H25: ='Model Engine'!D49*(1+$A25)-'Model Engine'!D42 | I25: ='Model Engine'!E49*(1+$A25)-'Model Engine'!E42 | J25: ='Model Engine'!F49*(1+$A25)-'Model Engine'!F42 | K25: ='Model Engine'!G49*(1+$A25)-'Model Engine'!G42 | L25: ='Model Engine'!H49*(1+$A25)-'Model Engine'!H42 | M25: ='Model Engine'!I49*(1+$A25)-'Model Engine'!I42 | ... Y25: ='Model Engine'!U49*(1+$A25)-'Model Engine'!U42
B26: =IFERROR(XIRR($F26:$Y26,'Model Engine'!$B$30:$U$30),"n/a") | C26: =IFERROR(SUMIF($F26:$Y26,">0")/(-SUMIF($F26:$Y26,"<0")),"n/a") | F26: ='Model Engine'!B49*(1+$A26)-'Model Engine'!B42 | G26: ='Model Engine'!C49*(1+$A26)-'Model Engine'!C42 | H26: ='Model Engine'!D49*(1+$A26)-'Model Engine'!D42 | I26: ='Model Engine'!E49*(1+$A26)-'Model Engine'!E42 | J26: ='Model Engine'!F49*(1+$A26)-'Model Engine'!F42 | K26: ='Model Engine'!G49*(1+$A26)-'Model Engine'!G42 | L26: ='Model Engine'!H49*(1+$A26)-'Model Engine'!H42 | M26: ='Model Engine'!I49*(1+$A26)-'Model Engine'!I42 | ... Y26: ='Model Engine'!U49*(1+$A26)-'Model Engine'!U42
A27: SENSITIVITY — COST SHIFT vs UNLEVERED IRR
A28: Cost Shift | B28: Unlev IRR | C28: MOIC (Unlev) | E28: Helper CF strip → | F28: P1 | G28: P2 | H28: P3 | I28: P4 | J28: P5 | K28: P6 | L28: P7 | M28: P8 | N28: P9 | O28: P10 | P28: P11 | Q28: P12 | R28: P13 | S28: P14 | T28: P15 | U28: P16 | V28: P17 | W28: P18 | X28: P19 | Y28: P20
A29: =Inputs!$B$53*-4 | B29: =IFERROR(XIRR($F29:$Y29,'Model Engine'!$B$30:$U$30),"n/a") | C29: =IFERROR(SUMIF($F29:$Y29,">0")/(-SUMIF($F29:$Y29,"<0")),"n/a") | F29: ='Model Engine'!B49-'Model Engine'!B42*(1+$A29) | G29: ='Model Engine'!C49-'Model Engine'!C42*(1+$A29) | H29: ='Model Engine'!D49-'Model Engine'!D42*(1+$A29) | I29: ='Model Engine'!E49-'Model Engine'!E42*(1+$A29) | J29: ='Model Engine'!F49-'Model Engine'!F42*(1+$A29) | K29: ='Model Engine'!G49-'Model Engine'!G42*(1+$A29) | L29: ='Model Engine'!H49-'Model Engine'!H42*(1+$A29) | M29: ='Model Engine'!I49-'Model Engine'!I42*(1+$A29) | ... Y29: ='Model Engine'!U49-'Model Engine'!U42*(1+$A29)
A30: =Inputs!$B$53*-3 | B30: =IFERROR(XIRR($F30:$Y30,'Model Engine'!$B$30:$U$30),"n/a") | C30: =IFERROR(SUMIF($F30:$Y30,">0")/(-SUMIF($F30:$Y30,"<0")),"n/a") | F30: ='Model Engine'!B49-'Model Engine'!B42*(1+$A30) | G30: ='Model Engine'!C49-'Model Engine'!C42*(1+$A30) | H30: ='Model Engine'!D49-'Model Engine'!D42*(1+$A30) | I30: ='Model Engine'!E49-'Model Engine'!E42*(1+$A30) | J30: ='Model Engine'!F49-'Model Engine'!F42*(1+$A30) | K30: ='Model Engine'!G49-'Model Engine'!G42*(1+$A30) | L30: ='Model Engine'!H49-'Model Engine'!H42*(1+$A30) | M30: ='Model Engine'!I49-'Model Engine'!I42*(1+$A30) | ... Y30: ='Model Engine'!U49-'Model Engine'!U42*(1+$A30)
A31: =Inputs!$B$53*-2 | B31: =IFERROR(XIRR($F31:$Y31,'Model Engine'!$B$30:$U$30),"n/a") | C31: =IFERROR(SUMIF($F31:$Y31,">0")/(-SUMIF($F31:$Y31,"<0")),"n/a") | F31: ='Model Engine'!B49-'Model Engine'!B42*(1+$A31) | G31: ='Model Engine'!C49-'Model Engine'!C42*(1+$A31) | H31: ='Model Engine'!D49-'Model Engine'!D42*(1+$A31) | I31: ='Model Engine'!E49-'Model Engine'!E42*(1+$A31) | J31: ='Model Engine'!F49-'Model Engine'!F42*(1+$A31) | K31: ='Model Engine'!G49-'Model Engine'!G42*(1+$A31) | L31: ='Model Engine'!H49-'Model Engine'!H42*(1+$A31) | M31: ='Model Engine'!I49-'Model Engine'!I42*(1+$A31) | ... Y31: ='Model Engine'!U49-'Model Engine'!U42*(1+$A31)
A32: =Inputs!$B$53*-1 | B32: =IFERROR(XIRR($F32:$Y32,'Model Engine'!$B$30:$U$30),"n/a") | C32: =IFERROR(SUMIF($F32:$Y32,">0")/(-SUMIF($F32:$Y32,"<0")),"n/a") | F32: ='Model Engine'!B49-'Model Engine'!B42*(1+$A32) | G32: ='Model Engine'!C49-'Model Engine'!C42*(1+$A32) | H32: ='Model Engine'!D49-'Model Engine'!D42*(1+$A32) | I32: ='Model Engine'!E49-'Model Engine'!E42*(1+$A32) | J32: ='Model Engine'!F49-'Model Engine'!F42*(1+$A32) | K32: ='Model Engine'!G49-'Model Engine'!G42*(1+$A32) | L32: ='Model Engine'!H49-'Model Engine'!H42*(1+$A32) | M32: ='Model Engine'!I49-'Model Engine'!I42*(1+$A32) | ... Y32: ='Model Engine'!U49-'Model Engine'!U42*(1+$A32)
A33: =Inputs!$B$53*0 | B33: =IFERROR(XIRR($F33:$Y33,'Model Engine'!$B$30:$U$30),"n/a") | C33: =IFERROR(SUMIF($F33:$Y33,">0")/(-SUMIF($F33:$Y33,"<0")),"n/a") | F33: ='Model Engine'!B49-'Model Engine'!B42*(1+$A33) | G33: ='Model Engine'!C49-'Model Engine'!C42*(1+$A33) | H33: ='Model Engine'!D49-'Model Engine'!D42*(1+$A33) | I33: ='Model Engine'!E49-'Model Engine'!E42*(1+$A33) | J33: ='Model Engine'!F49-'Model Engine'!F42*(1+$A33) | K33: ='Model Engine'!G49-'Model Engine'!G42*(1+$A33) | L33: ='Model Engine'!H49-'Model Engine'!H42*(1+$A33) | M33: ='Model Engine'!I49-'Model Engine'!I42*(1+$A33) | ... Y33: ='Model Engine'!U49-'Model Engine'!U42*(1+$A33)
A34: =Inputs!$B$53*1 | B34: =IFERROR(XIRR($F34:$Y34,'Model Engine'!$B$30:$U$30),"n/a") | C34: =IFERROR(SUMIF($F34:$Y34,">0")/(-SUMIF($F34:$Y34,"<0")),"n/a") | F34: ='Model Engine'!B49-'Model Engine'!B42*(1+$A34) | G34: ='Model Engine'!C49-'Model Engine'!C42*(1+$A34) | H34: ='Model Engine'!D49-'Model Engine'!D42*(1+$A34) | I34: ='Model Engine'!E49-'Model Engine'!E42*(1+$A34) | J34: ='Model Engine'!F49-'Model Engine'!F42*(1+$A34) | K34: ='Model Engine'!G49-'Model Engine'!G42*(1+$A34) | L34: ='Model Engine'!H49-'Model Engine'!H42*(1+$A34) | M34: ='Model Engine'!I49-'Model Engine'!I42*(1+$A34) | ... Y34: ='Model Engine'!U49-'Model Engine'!U42*(1+$A34)
A35: =Inputs!$B$53*2 | B35: =IFERROR(XIRR($F35:$Y35,'Model Engine'!$B$30:$U$30),"n/a") | C35: =IFERROR(SUMIF($F35:$Y35,">0")/(-SUMIF($F35:$Y35,"<0")),"n/a") | F35: ='Model Engine'!B49-'Model Engine'!B42*(1+$A35) | G35: ='Model Engine'!C49-'Model Engine'!C42*(1+$A35) | H35: ='Model Engine'!D49-'Model Engine'!D42*(1+$A35) | I35: ='Model Engine'!E49-'Model Engine'!E42*(1+$A35) | J35: ='Model Engine'!F49-'Model Engine'!F42*(1+$A35) | K35: ='Model Engine'!G49-'Model Engine'!G42*(1+$A35) | L35: ='Model Engine'!H49-'Model Engine'!H42*(1+$A35) | M35: ='Model Engine'!I49-'Model Engine'!I42*(1+$A35) | ... Y35: ='Model Engine'!U49-'Model Engine'!U42*(1+$A35)
A36: =Inputs!$B$53*3 | B36: =IFERROR(XIRR($F36:$Y36,'Model Engine'!$B$30:$U$30),"n/a") | C36: =IFERROR(SUMIF($F36:$Y36,">0")/(-SUMIF($F36:$Y36,"<0")),"n/a") | F36: ='Model Engine'!B49-'Model Engine'!B42*(1+$A36) | G36: ='Model Engine'!C49-'Model Engine'!C42*(1+$A36) | H36: ='Model Engine'!D49-'Model Engine'!D42*(1+$A36) | I36: ='Model Engine'!E49-'Model Engine'!E42*(1+$A36) | J36: ='Model Engine'!F49-'Model Engine'!F42*(1+$A36) | K36: ='Model Engine'!G49-'Model Engine'!G42*(1+$A36) | L36: ='Model Engine'!H49-'Model Engine'!H42*(1+$A36) | M36: ='Model Engine'!I49-'Model Engine'!I42*(1+$A36) | ... Y36: ='Model Engine'!U49-'Model Engine'!U42*(1+$A36)
A37: =Inputs!$B$53*4 | B37: =IFERROR(XIRR($F37:$Y37,'Model Engine'!$B$30:$U$30),"n/a") | C37: =IFERROR(SUMIF($F37:$Y37,">0")/(-SUMIF($F37:$Y37,"<0")),"n/a") | F37: ='Model Engine'!B49-'Model Engine'!B42*(1+$A37) | G37: ='Model Engine'!C49-'Model Engine'!C42*(1+$A37) | H37: ='Model Engine'!D49-'Model Engine'!D42*(1+$A37) | I37: ='Model Engine'!E49-'Model Engine'!E42*(1+$A37) | J37: ='Model Engine'!F49-'Model Engine'!F42*(1+$A37) | K37: ='Model Engine'!G49-'Model Engine'!G42*(1+$A37) | L37: ='Model Engine'!H49-'Model Engine'!H42*(1+$A37) | M37: ='Model Engine'!I49-'Model Engine'!I42*(1+$A37) | ... Y37: ='Model Engine'!U49-'Model Engine'!U42*(1+$A37)
A38: SENSITIVITY — EXIT PRICE SHIFT vs UNLEVERED IRR
A39: Exit Shift | B39: Unlev IRR | C39: MOIC (Unlev) | E39: Helper CF strip → | F39: P1 | G39: P2 | H39: P3 | I39: P4 | J39: P5 | K39: P6 | L39: P7 | M39: P8 | N39: P9 | O39: P10 | P39: P11 | Q39: P12 | R39: P13 | S39: P14 | T39: P15 | U39: P16 | V39: P17 | W39: P18 | X39: P19 | Y39: P20
A40: =Inputs!$B$54*-4 | B40: =IFERROR(XIRR($F40:$Y40,'Model Engine'!$B$30:$U$30),"n/a") | C40: =IFERROR(SUMIF($F40:$Y40,">0")/(-SUMIF($F40:$Y40,"<0")),"n/a") | F40: =('Model Engine'!B44+'Model Engine'!B45*(1+$A40))*(1-Inputs!$B$32-Inputs!$B$33)-'Model Engine'!B42 | G40: =('Model Engine'!C44+'Model Engine'!C45*(1+$A40))*(1-Inputs!$B$32-Inputs!$B$33)-'Model Engine'!C42 | H40: =('Model Engine'!D44+'Model Engine'!D45*(1+$A40))*(1-Inputs!$B$32-Inputs!$B$33)-'Model Engine'!D42 | I40: =('Model Engine'!E44+'Model Engine'!E45*(1+$A40))*(1-Inputs!$B$32-Inputs!$B$33)-'Model Engine'!E42 | J40: =('Model Engine'!F44+'Model Engine'!F45*(1+$A40))*(1-Inputs!$B$32-Inputs!$B$33)-'Model Engine'!F42 | K40: =('Model Engine'!G44+'Model Engine'!G45*(1+$A40))*(1-Inputs!$B$32-Inputs!$B$33)-'Model Engine'!G42 | L40: =('Model Engine'!H44+'Model Engine'!H45*(1+$A40))*(1-Inputs!$B$32-Inputs!$B$33)-'Model Engine'!H42 | M40: =('Model Engine'!I44+'Model Engine'!I45*(1+$A40))*(1-Inputs!$B$32-Inputs!$B$33)-'Model Engine'!I42 | ... Y40: =('Model Engine'!U44+'Model Engine'!U45*(1+$A40))*(1-Inputs!$B$32-Inputs!$B$33)-'Model Engine'!U42
A41: =Inputs!$B$54*-3 | B41: =IFERROR(XIRR($F41:$Y41,'Model Engine'!$B$30:$U$30),"n/a") | C41: =IFERROR(SUMIF($F41:$Y41,">0")/(-SUMIF($F41:$Y41,"<0")),"n/a") | F41: =('Model Engine'!B44+'Model Engine'!B45*(1+$A41))*(1-Inputs!$B$32-Inputs!$B$33)-'Model Engine'!B42 | G41: =('Model Engine'!C44+'Model Engine'!C45*(1+$A41))*(1-Inputs!$B$32-Inputs!$B$33)-'Model Engine'!C42 | H41: =('Model Engine'!D44+'Model Engine'!D45*(1+$A41))*(1-Inputs!$B$32-Inputs!$B$33)-'Model Engine'!D42 | I41: =('Model Engine'!E44+'Model Engine'!E45*(1+$A41))*(1-Inputs!$B$32-Inputs!$B$33)-'Model Engine'!E42 | J41: =('Model Engine'!F44+'Model Engine'!F45*(1+$A41))*(1-Inputs!$B$32-Inputs!$B$33)-'Model Engine'!F42 | K41: =('Model Engine'!G44+'Model Engine'!G45*(1+$A41))*(1-Inputs!$B$32-Inputs!$B$33)-'Model Engine'!G42 | L41: =('Model Engine'!H44+'Model Engine'!H45*(1+$A41))*(1-Inputs!$B$32-Inputs!$B$33)-'Model Engine'!H42 | M41: =('Model Engine'!I44+'Model Engine'!I45*(1+$A41))*(1-Inputs!$B$32-Inputs!$B$33)-'Model Engine'!I42 | ... Y41: =('Model Engine'!U44+'Model Engine'!U45*(1+$A41))*(1-Inputs!$B$32-Inputs!$B$33)-'Model Engine'!U42
A42: =Inputs!$B$54*-2 | B42: =IFERROR(XIRR($F42:$Y42,'Model Engine'!$B$30:$U$30),"n/a") | C42: =IFERROR(SUMIF($F42:$Y42,">0")/(-SUMIF($F42:$Y42,"<0")),"n/a") | F42: =('Model Engine'!B44+'Model Engine'!B45*(1+$A42))*(1-Inputs!$B$32-Inputs!$B$33)-'Model Engine'!B42 | G42: =('Model Engine'!C44+'Model Engine'!C45*(1+$A42))*(1-Inputs!$B$32-Inputs!$B$33)-'Model Engine'!C42 | H42: =('Model Engine'!D44+'Model Engine'!D45*(1+$A42))*(1-Inputs!$B$32-Inputs!$B$33)-'Model Engine'!D42 | I42: =('Model Engine'!E44+'Model Engine'!E45*(1+$A42))*(1-Inputs!$B$32-Inputs!$B$33)-'Model Engine'!E42 | J42: =('Model Engine'!F44+'Model Engine'!F45*(1+$A42))*(1-Inputs!$B$32-Inputs!$B$33)-'Model Engine'!F42 | K42: =('Model Engine'!G44+'Model Engine'!G45*(1+$A42))*(1-Inputs!$B$32-Inputs!$B$33)-'Model Engine'!G42 | L42: =('Model Engine'!H44+'Model Engine'!H45*(1+$A42))*(1-Inputs!$B$32-Inputs!$B$33)-'Model Engine'!H42 | M42: =('Model Engine'!I44+'Model Engine'!I45*(1+$A42))*(1-Inputs!$B$32-Inputs!$B$33)-'Model Engine'!I42 | ... Y42: =('Model Engine'!U44+'Model Engine'!U45*(1+$A42))*(1-Inputs!$B$32-Inputs!$B$33)-'Model Engine'!U42
...
